2023-05-27 22:41:06.267 ERROR (SyncWorker_0) [homeassistant.util.yaml.loader] while scanning for the next token
found character '\t' that cannot start any token
  in "/config/configuration.yaml", line 14, column 1
2023-05-27 22:41:06.274 ERROR (MainThread) [homeassistant.bootstrap] Failed to parse configuration.yaml: while scanning for the next token
found character '\t' that cannot start any token
  in "/config/configuration.yaml", line 14, column 1. Activating safe mode
2023-05-27 22:42:31.366 ERROR (MainThread) [aiohttp.server] Unhandled exception
Traceback (most recent call last):
  File "/usr/local/lib/python3.10/asyncio/base_events.py", line 1205, in _sendfile_fallback
    read = await self.run_in_executor(None, file.readinto, view)
asyncio.exceptions.CancelledError

During handling of the above exception, another exception occurred:

Traceback (most recent call last):
  File "/usr/local/lib/python3.10/site-packages/aiohttp/web_protocol.py", line 512, in start
    resp, reset = await task
  File "/usr/local/lib/python3.10/site-packages/aiohttp/web_protocol.py", line 458, in _handle_request
    reset = await self.finish_response(request, resp, start_time)
  File "/usr/local/lib/python3.10/site-packages/aiohttp/web_protocol.py", line 611, in finish_response
    await prepare_meth(request)
  File "/usr/local/lib/python3.10/site-packages/aiohttp/web_fileresponse.py", line 286, in prepare
    return await self._sendfile(request, fobj, offset, count)
  File "/usr/local/lib/python3.10/site-packages/aiohttp/web_fileresponse.py", line 99, in _sendfile
    await loop.sendfile(transport, fobj, offset, count)
  File "/usr/local/lib/python3.10/asyncio/base_events.py", line 1184, in sendfile
    return await self._sendfile_fallback(transport, file,
  File "/usr/local/lib/python3.10/asyncio/base_events.py", line 1214, in _sendfile_fallback
    await proto.restore()
  File "/usr/local/lib/python3.10/asyncio/base_events.py", line 268, in restore
    self._transport.resume_reading()
  File "/usr/local/lib/python3.10/asyncio/sslproto.py", line 343, in resume_reading
    self._ssl_protocol._transport.resume_reading()
AttributeError: 'NoneType' object has no attribute 'resume_reading'
2023-05-27 22:42:40.366 WARNING (MainThread) [homeassistant.components.http.ban] Login attempt or request with invalid authentication from 192.168.1.117 (192.168.1.117). Requested URL: '/auth/login_flow/fbcb0d87b438f6222ab758cca06ed11a'. (Mozilla/5.0 (Macintosh; Intel Mac OS X 10_15_7) AppleWebKit/537.36 (KHTML, like Gecko) Chrome/113.0.0.0 Safari/537.36)
2023-05-27 22:43:05.039 ERROR (MainThread) [aiohttp.server] Unhandled exception
Traceback (most recent call last):
  File "/usr/local/lib/python3.10/asyncio/base_events.py", line 1205, in _sendfile_fallback
    read = await self.run_in_executor(None, file.readinto, view)
asyncio.exceptions.CancelledError

During handling of the above exception, another exception occurred:

Traceback (most recent call last):
  File "/usr/local/lib/python3.10/site-packages/aiohttp/web_protocol.py", line 512, in start
    resp, reset = await task
  File "/usr/local/lib/python3.10/site-packages/aiohttp/web_protocol.py", line 458, in _handle_request
    reset = await self.finish_response(request, resp, start_time)
  File "/usr/local/lib/python3.10/site-packages/aiohttp/web_protocol.py", line 611, in finish_response
    await prepare_meth(request)
  File "/usr/local/lib/python3.10/site-packages/aiohttp/web_fileresponse.py", line 286, in prepare
    return await self._sendfile(request, fobj, offset, count)
  File "/usr/local/lib/python3.10/site-packages/aiohttp/web_fileresponse.py", line 99, in _sendfile
    await loop.sendfile(transport, fobj, offset, count)
  File "/usr/local/lib/python3.10/asyncio/base_events.py", line 1184, in sendfile
    return await self._sendfile_fallback(transport, file,
  File "/usr/local/lib/python3.10/asyncio/base_events.py", line 1214, in _sendfile_fallback
    await proto.restore()
  File "/usr/local/lib/python3.10/asyncio/base_events.py", line 268, in restore
    self._transport.resume_reading()
  File "/usr/local/lib/python3.10/asyncio/sslproto.py", line 343, in resume_reading
    self._ssl_protocol._transport.resume_reading()
AttributeError: 'NoneType' object has no attribute 'resume_reading'
2023-05-27 22:47:09.108 ERROR (MainThread) [aiohttp.server] Unhandled exception
Traceback (most recent call last):
  File "/usr/local/lib/python3.10/asyncio/base_events.py", line 1205, in _sendfile_fallback
    read = await self.run_in_executor(None, file.readinto, view)
asyncio.exceptions.CancelledError

During handling of the above exception, another exception occurred:

Traceback (most recent call last):
  File "/usr/local/lib/python3.10/site-packages/aiohttp/web_protocol.py", line 512, in start
    resp, reset = await task
  File "/usr/local/lib/python3.10/site-packages/aiohttp/web_protocol.py", line 458, in _handle_request
    reset = await self.finish_response(request, resp, start_time)
  File "/usr/local/lib/python3.10/site-packages/aiohttp/web_protocol.py", line 611, in finish_response
    await prepare_meth(request)
  File "/usr/local/lib/python3.10/site-packages/aiohttp/web_fileresponse.py", line 286, in prepare
    return await self._sendfile(request, fobj, offset, count)
  File "/usr/local/lib/python3.10/site-packages/aiohttp/web_fileresponse.py", line 99, in _sendfile
    await loop.sendfile(transport, fobj, offset, count)
  File "/usr/local/lib/python3.10/asyncio/base_events.py", line 1184, in sendfile
    return await self._sendfile_fallback(transport, file,
  File "/usr/local/lib/python3.10/asyncio/base_events.py", line 1214, in _sendfile_fallback
    await proto.restore()
  File "/usr/local/lib/python3.10/asyncio/base_events.py", line 268, in restore
    self._transport.resume_reading()
  File "/usr/local/lib/python3.10/asyncio/sslproto.py", line 343, in resume_reading
    self._ssl_protocol._transport.resume_reading()
AttributeError: 'NoneType' object has no attribute 'resume_reading'
2023-05-27 23:14:26.946 ERROR (SyncWorker_3) [homeassistant.util.yaml.loader] while scanning for the next token
found character '\t' that cannot start any token
  in "/config/configuration.yaml", line 14, column 1
